Workbook
Name Account: Categories!$A$1:$A$14
Name AccountCode: Categories!$A$1:$A$14
Name Accountcodes: Categories!$A$1:$A$14
Name Income_1: Categories!$A$1:$A$14

Sheet Instructions
A1: Setup Instructions
C3: Lucy's Tailored Tails
B6: Bank Opening Balance | C6: 0 | D6: If you have a separate business bank account, update this field with the bank balance at the start of your financial year
B7: Month | C7: April | D7: Leave this - keep the book starting from April - this helps for tax.
A10: Overwrite the Category list in Col A on the next tab to reflect your different income and expenditure types
B11: The first income and expenditure types have been changed for you as an example to 'Shop Sales' and 'Website Fees', you can overwrite these. Do not add or remove any columns or rows, so keep to a max of 5 income types.
B12: Examples of income may include different types of services, this helps to track what you are selling.
B13: Examples of expenses include items such as website fees, software subscriptions, telephone costs, and items purchased to run your business. Make sure you include types for bank interest and charges.
B14: These items form a picklist for you to choose from as you record your transactions in the monthly tabs.
A16: Enter your income and expenses in on the monthly tabs (Column A to D only) when they are incurred, not when the cash is received or paid
B17: This is known as the Accruals basis (rather than cash basis) and helps to provide a more accurate picture of your business activities.
B18: For example, if you complete work in July but don't get paid until August, enter the income in July. If you purchase something in July that is payable in August, enter the expense in July.
B19: If you decide to withdraw any funds from your business bank account for personal use, set up an expense type for 'Drawings' and record the transaction
B20: Enter amounts including any VAT.
A22: At the end of each month check that the bank balance in the spreadsheet (Column Y) matches the one on your bank statement
B23: This assumes you have set up a separate bank account, which is strongly advised. If you haven't, you can continue to use the spreadsheet as normal and ignore the bank balance at the end of each sheet
B24: If you transfer an opening balance into your new bank account, create an income type called 'Capital' and use that to record the transaction as an income.
B25: You may need to add items that you see on your bank statement at the end of the month to this tracker, such as interest and bank charges, in order to make the amounts match.
B26: If the balances do not match this is due to income that you have booked but not received payment for yet, or items that have been purchased but not yet paid for. This is ok and expected.
A28: Be consistent with customer and supplier names
B29: This helps when reviewing activities at quarter or month end and allows transactions to be grouped together correctly
B30: For example - don't use 'Royal Mail' and 'Post Office'. Use the same customer and supplier names throughout.
B31: Keep dates consistent too (any format you like)

Sheet Categories
A1: Overwrite this list with your income and expense categories
A2: Shop Sales | B2: Inc1 | C2: example, change as needed
A3: Income 2 | B3: Inc2
A4: Income 3 | B4: Int
A5: Income 4 | B5: Inc4
A6: Income 5 | B6: Inc5
A7: Website Fees | B7: ExpA | C7: example, change as needed
A8: Exp 2 | B8: ExpB
A9: Exp 3 | B9: ExpC
A10: Exp 4 | B10: ExpD
A11: Exp 5 | B11: ExpE
A12: Exp 6 | B12: ExpF
A13: Exp 7 | B13: ExpG
A14: Exp 8 | B14: ExpH
A15: Exp 9 | B15: ExpI
A16: Exp 10 | B16: ExpJ
A17: Exp 11 | B17: ExpK
A18: Exp 12 | B18: ExpL
A19: Exp 13 | B19: ExpM
A22: January
A23: February
A24: March
A25: April
A26: May
A27: June
A28: July
A29: August
A30: September
A31: October
A32: November
A33: December

Sheet Apr
A1: Cash Book April | D1: =Instructions!C3 -> Lucy's Tailored Tails
R3: Bank balance B/f | Y3: =IF(Instructions!C7="April",Instructions!C6,Mar!Y95) -> 0
A4: UPDATE THESE COLUMNS ONLY | G4: Income | L4: Expenditure
A5: Date | B5: Customer or Supplier | C5: Reference | D5: Amount | E5: Category | G5: =Categories!A2 -> Shop Sales | H5: =Categories!A3 -> Income 2 | I5: =Categories!A4 -> Income 3 | J5: =Categories!A5 -> Income 4 | K5: =Categories!A6 -> Income 5 | L5: =Categories!A7 -> Website Fees | M5: =Categories!A8 -> Exp 2 | N5: =Categories!A9 -> Exp 3 | O5: =Categories!A10 -> Exp 4 | P5: =Categories!A11 -> Exp 5 | Q5: =Categories!A12 -> Exp 6 | R5: =Categories!A13 -> Exp 7 | S5: =Categories!A14 -> Exp 8 | T5: =Categories!A15 -> Exp 9 | U5: =Categories!A16 -> Exp 10 | V5: =Categories!A17 -> Exp 11 | W5: =Categories!A18 -> Exp 12 | X5: =Categories!A19 -> Exp 13 | Y5: Balance
E6: Choose Account | F6: =IF($E6=Categories!$A$1,"",IF($E6=Categories!$A$2,Categories!$B$2,IF($E6=Categories!$A$3,Categories!$B$3,IF($E6=Categories!$A$4,Categories!$B$4,IF($E6=Categories!$A$5,Categories!$B$5,IF($E6=Categories!$A$6,Categories!$B$6,IF($E6=Categories!$A$7,Categories!$B$7,IF($E6=Categories!$A$8,Categories!$B$8,IF($E6=Categories!$A$9,Categories!$B$9,IF($E6=Categories!$A$10,Categories!$B$10,IF($E6=Categories!$A$11,Categories!$B$11,IF($E6=Categories!$A$12,Categories!$B$12,IF($E6=Categories!$A$13,Categories!$B$13,IF($E6=Categories!$A$14,Categories!$B$14,IF($E6=Categories!$A$15,Categories!$B$15,IF($E6=Categories!$A$16,Categories!$B$16,IF($E6=Categories!$A$17,Categories!$B$17,IF($E6=Categories!$A$18,Categories!$B$18,IF($E6=Categories!$A$19,Categories!$B$19))))))))))))))))))) -> FALSE | G6: =IF($F6="Inc1",$D6,"") | H6: =IF($F6="Inc2",$D6,"") | I6: =IF($F6="Int",$D6,"") | J6: =IF($F6="Inc4",$D6,"") | K6: =IF($F6="Inc5",$D6,"") | L6: =IF($F6="ExpA",$D6,"") | M6: =IF($F6="ExpB",$D6,"") | N6: =IF($F6="ExpC",$D6,"") | O6: =IF($F6="ExpD",$D6,"") | P6: =IF($F6="ExpE",$D6,"") | Q6: =IF($F6="ExpF",$D6,"") | R6: =IF($F6="ExpG",$D6,"") | S6: =IF($F6="ExpH",$D6,"") | T6: =IF($F6="ExpI",$D6,"") | U6: =IF($F6="ExpJ",$D6,"") | V6: =IF($F6="ExpK",$D6,"") | W6: =IF($F6="ExpL",$D6,"") | X6: =IF($F6="Expm",$D6,"") | Y6: =$Y$3+SUM(G6:K6)-SUM(L6:X6) -> 0
E7: Choose Account | F7: =IF($E7=Categories!$A$1,"",IF($E7=Categories!$A$2,Categories!$B$2,IF($E7=Categories!$A$3,Categories!$B$3,IF($E7=Categories!$A$4,Categories!$B$4,IF($E7=Categories!$A$5,Categories!$B$5,IF($E7=Categories!$A$6,Categories!$B$6,IF($E7=Categories!$A$7,Categories!$B$7,IF($E7=Categories!$A$8,Categories!$B$8,IF($E7=Categories!$A$9,Categories!$B$9,IF($E7=Categories!$A$10,Categories!$B$10,IF($E7=Categories!$A$11,Categories!$B$11,IF($E7=Categories!$A$12,Categories!$B$12,IF($E7=Categories!$A$13,Categories!$B$13,IF($E7=Categories!$A$14,Categories!$B$14,IF($E7=Categories!$A$15,Categories!$B$15,IF($E7=Categories!$A$16,Categories!$B$16,IF($E7=Categories!$A$17,Categories!$B$17,IF($E7=Categories!$A$18,Categories!$B$18,IF($E7=Categories!$A$19,Categories!$B$19))))))))))))))))))) -> FALSE | G7: =IF($F7="Inc1",$D7,"") | H7: =IF($F7="Inc2",$D7,"") | I7: =IF($F7="Int",$D7,"") | J7: =IF($F7="Inc4",$D7,"") | K7: =IF($F7="Inc5",$D7,"") | L7: =IF($F7="ExpA",$D7,"") | M7: =IF($F7="ExpB",$D7,"") | N7: =IF($F7="ExpC",$D7,"") | O7: =IF($F7="ExpD",$D7,"") | P7: =IF($F7="ExpE",$D7,"") | Q7: =IF($F7="ExpF",$D7,"") | R7: =IF($F7="ExpG",$D7,"") | S7: =IF($F7="ExpH",$D7,"") | T7: =IF($F7="ExpI",$D7,"") | U7: =IF($F7="ExpJ",$D7,"") | V7: =IF($F7="ExpK",$D7,"") | W7: =IF($F7="ExpL",$D7,"") | X7: =IF($F7="Expm",$D7,"") | Y7: =Y6+SUM(G7:K7)-SUM(L7:X7) -> 0
E8: Choose Account | F8: =IF($E8=Categories!$A$1,"",IF($E8=Categories!$A$2,Categories!$B$2,IF($E8=Categories!$A$3,Categories!$B$3,IF($E8=Categories!$A$4,Categories!$B$4,IF($E8=Categories!$A$5,Categories!$B$5,IF($E8=Categories!$A$6,Categories!$B$6,IF($E8=Categories!$A$7,Categories!$B$7,IF($E8=Categories!$A$8,Categories!$B$8,IF($E8=Categories!$A$9,Categories!$B$9,IF($E8=Categories!$A$10,Categories!$B$10,IF($E8=Categories!$A$11,Categories!$B$11,IF($E8=Categories!$A$12,Categories!$B$12,IF($E8=Categories!$A$13,Categories!$B$13,IF($E8=Categories!$A$14,Categories!$B$14,IF($E8=Categories!$A$15,Categories!$B$15,IF($E8=Categories!$A$16,Categories!$B$16,IF($E8=Categories!$A$17,Categories!$B$17,IF($E8=Categories!$A$18,Categories!$B$18,IF($E8=Categories!$A$19,Categories!$B$19))))))))))))))))))) -> FALSE | G8: =IF($F8="Inc1",$D8,"") | H8: =IF($F8="Inc2",$D8,"") | I8: =IF($F8="Int",$D8,"") | J8: =IF($F8="Inc4",$D8,"") | K8: =IF($F8="Inc5",$D8,"") | L8: =IF($F8="ExpA",$D8,"") | M8: =IF($F8="ExpB",$D8,"") | N8: =IF($F8="ExpC",$D8,"") | O8: =IF($F8="ExpD",$D8,"") | P8: =IF($F8="ExpE",$D8,"") | Q8: =IF($F8="ExpF",$D8,"") | R8: =IF($F8="ExpG",$D8,"") | S8: =IF($F8="ExpH",$D8,"") | T8: =IF($F8="ExpI",$D8,"") | U8: =IF($F8="ExpJ",$D8,"") | V8: =IF($F8="ExpK",$D8,"") | W8: =IF($F8="ExpL",$D8,"") | X8: =IF($F8="Expm",$D8,"") | Y8: =Y7+SUM(G8:K8)-SUM(L8:X8) -> 0
E9: Choose Account | F9: =IF($E9=Categories!$A$1,"",IF($E9=Categories!$A$2,Categories!$B$2,IF($E9=Categories!$A$3,Categories!$B$3,IF($E9=Categories!$A$4,Categories!$B$4,IF($E9=Categories!$A$5,Categories!$B$5,IF($E9=Categories!$A$6,Categories!$B$6,IF($E9=Categories!$A$7,Categories!$B$7,IF($E9=Categories!$A$8,Categories!$B$8,IF($E9=Categories!$A$9,Categories!$B$9,IF($E9=Categories!$A$10,Categories!$B$10,IF($E9=Categories!$A$11,Categories!$B$11,IF($E9=Categories!$A$12,Categories!$B$12,IF($E9=Categories!$A$13,Categories!$B$13,IF($E9=Categories!$A$14,Categories!$B$14,IF($E9=Categories!$A$15,Categories!$B$15,IF($E9=Categories!$A$16,Categories!$B$16,IF($E9=Categories!$A$17,Categories!$B$17,IF($E9=Categories!$A$18,Categories!$B$18,IF($E9=Categories!$A$19,Categories!$B$19))))))))))))))))))) -> FALSE | G9: =IF($F9="Inc1",$D9,"") | H9: =IF($F9="Inc2",$D9,"") | I9: =IF($F9="Int",$D9,"") | J9: =IF($F9="Inc4",$D9,"") | K9: =IF($F9="Inc5",$D9,"") | L9: =IF($F9="ExpA",$D9,"") | M9: =IF($F9="ExpB",$D9,"") | N9: =IF($F9="ExpC",$D9,"") | O9: =IF($F9="ExpD",$D9,"") | P9: =IF($F9="ExpE",$D9,"") | Q9: =IF($F9="ExpF",$D9,"") | R9: =IF($F9="ExpG",$D9,"") | S9: =IF($F9="ExpH",$D9,"") | T9: =IF($F9="ExpI",$D9,"") | U9: =IF($F9="ExpJ",$D9,"") | V9: =IF($F9="ExpK",$D9,"") | W9: =IF($F9="ExpL",$D9,"") | X9: =IF($F9="Expm",$D9,"") | Y9: =Y8+SUM(G9:K9)-SUM(L9:X9) -> 0
E10: Choose Account | F10: =IF($E10=Categories!$A$1,"",IF($E10=Categories!$A$2,Categories!$B$2,IF($E10=Categories!$A$3,Categories!$B$3,IF($E10=Categories!$A$4,Categories!$B$4,IF($E10=Categories!$A$5,Categories!$B$5,IF($E10=Categories!$A$6,Categories!$B$6,IF($E10=Categories!$A$7,Categories!$B$7,IF($E10=Categories!$A$8,Categories!$B$8,IF($E10=Categories!$A$9,Categories!$B$9,IF($E10=Categories!$A$10,Categories!$B$10,IF($E10=Categories!$A$11,Categories!$B$11,IF($E10=Categories!$A$12,Categories!$B$12,IF($E10=Categories!$A$13,Categories!$B$13,IF($E10=Categories!$A$14,Categories!$B$14,IF($E10=Categories!$A$15,Categories!$B$15,IF($E10=Categories!$A$16,Categories!$B$16,IF($E10=Categories!$A$17,Categories!$B$17,IF($E10=Categories!$A$18,Categories!$B$18,IF($E10=Categories!$A$19,Categories!$B$19))))))))))))))))))) -> FALSE | G10: =IF($F10="Inc1",$D10,"") | H10: =IF($F10="Inc2",$D10,"") | I10: =IF($F10="Int",$D10,"") | J10: =IF($F10="Inc4",$D10,"") | K10: =IF($F10="Inc5",$D10,"") | L10: =IF($F10="ExpA",$D10,"") | M10: =IF($F10="ExpB",$D10,"") | N10: =IF($F10="ExpC",$D10,"") | O10: =IF($F10="ExpD",$D10,"") | P10: =IF($F10="ExpE",$D10,"") | Q10: =IF($F10="ExpF",$D10,"") | R10: =IF($F10="ExpG",$D10,"") | S10: =IF($F10="ExpH",$D10,"") | T10: =IF($F10="ExpI",$D10,"") | U10: =IF($F10="ExpJ",$D10,"") | V10: =IF($F10="ExpK",$D10,"") | W10: =IF($F10="ExpL",$D10,"") | X10: =IF($F10="Expm",$D10,"") | Y10: =Y9+SUM(G10:K10)-SUM(L10:X10) -> 0
E11: Choose Account | F11: =IF($E11=Categories!$A$1,"",IF($E11=Categories!$A$2,Categories!$B$2,IF($E11=Categories!$A$3,Categories!$B$3,IF($E11=Categories!$A$4,Categories!$B$4,IF($E11=Categories!$A$5,Categories!$B$5,IF($E11=Categories!$A$6,Categories!$B$6,IF($E11=Categories!$A$7,Categories!$B$7,IF($E11=Categories!$A$8,Categories!$B$8,IF($E11=Categories!$A$9,Categories!$B$9,IF($E11=Categories!$A$10,Categories!$B$10,IF($E11=Categories!$A$11,Categories!$B$11,IF($E11=Categories!$A$12,Categories!$B$12,IF($E11=Categories!$A$13,Categories!$B$13,IF($E11=Categories!$A$14,Categories!$B$14,IF($E11=Categories!$A$15,Categories!$B$15,IF($E11=Categories!$A$16,Categories!$B$16,IF($E11=Categories!$A$17,Categories!$B$17,IF($E11=Categories!$A$18,Categories!$B$18,IF($E11=Categories!$A$19,Categories!$B$19))))))))))))))))))) -> FALSE | G11: =IF($F11="Inc1",$D11,"") | H11: =IF($F11="Inc2",$D11,"") | I11: =IF($F11="Int",$D11,"") | J11: =IF($F11="Inc4",$D11,"") | K11: =IF($F11="Inc5",$D11,"") | L11: =IF($F11="ExpA",$D11,"") | M11: =IF($F11="ExpB",$D11,"") | N11: =IF($F11="ExpC",$D11,"") | O11: =IF($F11="ExpD",$D11,"") | P11: =IF($F11="ExpE",$D11,"") | Q11: =IF($F11="ExpF",$D11,"") | R11: =IF($F11="ExpG",$D11,"") | S11: =IF($F11="ExpH",$D11,"") | T11: =IF($F11="ExpI",$D11,"") | U11: =IF($F11="ExpJ",$D11,"") | V11: =IF($F11="ExpK",$D11,"") | W11: =IF($F11="ExpL",$D11,"") | X11: =IF($F11="Expm",$D11,"") | Y11: =Y10+SUM(G11:K11)-SUM(L11:X11) -> 0
E12: Choose Account | F12: =IF($E12=Categories!$A$1,"",IF($E12=Categories!$A$2,Categories!$B$2,IF($E12=Categories!$A$3,Categories!$B$3,IF($E12=Categories!$A$4,Categories!$B$4,IF($E12=Categories!$A$5,Categories!$B$5,IF($E12=Categories!$A$6,Categories!$B$6,IF($E12=Categories!$A$7,Categories!$B$7,IF($E12=Categories!$A$8,Categories!$B$8,IF($E12=Categories!$A$9,Categories!$B$9,IF($E12=Categories!$A$10,Categories!$B$10,IF($E12=Categories!$A$11,Categories!$B$11,IF($E12=Categories!$A$12,Categories!$B$12,IF($E12=Categories!$A$13,Categories!$B$13,IF($E12=Categories!$A$14,Categories!$B$14,IF($E12=Categories!$A$15,Categories!$B$15,IF($E12=Categories!$A$16,Categories!$B$16,IF($E12=Categories!$A$17,Categories!$B$17,IF($E12=Categories!$A$18,Categories!$B$18,IF($E12=Categories!$A$19,Categories!$B$19))))))))))))))))))) -> FALSE | G12: =IF($F12="Inc1",$D12,"") | H12: =IF($F12="Inc2",$D12,"") | I12: =IF($F12="Int",$D12,"") | J12: =IF($F12="Inc4",$D12,"") | K12: =IF($F12="Inc5",$D12,"") | L12: =IF($F12="ExpA",$D12,"") | M12: =IF($F12="ExpB",$D12,"") | N12: =IF($F12="ExpC",$D12,"") | O12: =IF($F12="ExpD",$D12,"") | P12: =IF($F12="ExpE",$D12,"") | Q12: =IF($F12="ExpF",$D12,"") | R12: =IF($F12="ExpG",$D12,"") | S12: =IF($F12="ExpH",$D12,"") | T12: =IF($F12="ExpI",$D12,"") | U12: =IF($F12="ExpJ",$D12,"") | V12: =IF($F12="ExpK",$D12,"") | W12: =IF($F12="ExpL",$D12,"") | X12: =IF($F12="Expm",$D12,"") | Y12: =Y11+SUM(G12:K12)-SUM(L12:X12) -> 0
E13: Choose Account | F13: =IF($E13=Categories!$A$1,"",IF($E13=Categories!$A$2,Categories!$B$2,IF($E13=Categories!$A$3,Categories!$B$3,IF($E13=Categories!$A$4,Categories!$B$4,IF($E13=Categories!$A$5,Categories!$B$5,IF($E13=Categories!$A$6,Categories!$B$6,IF($E13=Categories!$A$7,Categories!$B$7,IF($E13=Categories!$A$8,Categories!$B$8,IF($E13=Categories!$A$9,Categories!$B$9,IF($E13=Categories!$A$10,Categories!$B$10,IF($E13=Categories!$A$11,Categories!$B$11,IF($E13=Categories!$A$12,Categories!$B$12,IF($E13=Categories!$A$13,Categories!$B$13,IF($E13=Categories!$A$14,Categories!$B$14,IF($E13=Categories!$A$15,Categories!$B$15,IF($E13=Categories!$A$16,Categories!$B$16,IF($E13=Categories!$A$17,Categories!$B$17,IF($E13=Categories!$A$18,Categories!$B$18,IF($E13=Categories!$A$19,Categories!$B$19))))))))))))))))))) -> FALSE | G13: =IF($F13="Inc1",$D13,"") | H13: =IF($F13="Inc2",$D13,"") | I13: =IF($F13="Int",$D13,"") | J13: =IF($F13="Inc4",$D13,"") | K13: =IF($F13="Inc5",$D13,"") | L13: =IF($F13="ExpA",$D13,"") | M13: =IF($F13="ExpB",$D13,"") | N13: =IF($F13="ExpC",$D13,"") | O13: =IF($F13="ExpD",$D13,"") | P13: =IF($F13="ExpE",$D13,"") | Q13: =IF($F13="ExpF",$D13,"") | R13: =IF($F13="ExpG",$D13,"") | S13: =IF($F13="ExpH",$D13,"") | T13: =IF($F13="ExpI",$D13,"") | U13: =IF($F13="ExpJ",$D13,"") | V13: =IF($F13="ExpK",$D13,"") | W13: =IF($F13="ExpL",$D13,"") | X13: =IF($F13="Expm",$D13,"") | Y13: =Y12+SUM(G13:K13)-SUM(L13:X13) -> 0
E14: Choose Account | F14: =IF($E14=Categories!$A$1,"",IF($E14=Categories!$A$2,Categories!$B$2,IF($E14=Categories!$A$3,Categories!$B$3,IF($E14=Categories!$A$4,Categories!$B$4,IF($E14=Categories!$A$5,Categories!$B$5,IF($E14=Categories!$A$6,Categories!$B$6,IF($E14=Categories!$A$7,Categories!$B$7,IF($E14=Categories!$A$8,Categories!$B$8,IF($E14=Categories!$A$9,Categories!$B$9,IF($E14=Categories!$A$10,Categories!$B$10,IF($E14=Categories!$A$11,Categories!$B$11,IF($E14=Categories!$A$12,Categories!$B$12,IF($E14=Categories!$A$13,Categories!$B$13,IF($E14=Categories!$A$14,Categories!$B$14,IF($E14=Categories!$A$15,Categories!$B$15,IF($E14=Categories!$A$16,Categories!$B$16,IF($E14=Categories!$A$17,Categories!$B$17,IF($E14=Categories!$A$18,Categories!$B$18,IF($E14=Categories!$A$19,Categories!$B$19))))))))))))))))))) -> FALSE | G14: =IF($F14="Inc1",$D14,"") | H14: =IF($F14="Inc2",$D14,"") | I14: =IF($F14="Int",$D14,"") | J14: =IF($F14="Inc4",$D14,"") | K14: =IF($F14="Inc5",$D14,"") | L14: =IF($F14="ExpA",$D14,"") | M14: =IF($F14="ExpB",$D14,"") | N14: =IF($F14="ExpC",$D14,"") | O14: =IF($F14="ExpD",$D14,"") | P14: =IF($F14="ExpE",$D14,"") | Q14: =IF($F14="ExpF",$D14,"") | R14: =IF($F14="ExpG",$D14,"") | S14: =IF($F14="ExpH",$D14,"") | T14: =IF($F14="ExpI",$D14,"") | U14: =IF($F14="ExpJ",$D14,"") | V14: =IF($F14="ExpK",$D14,"") | W14: =IF($F14="ExpL",$D14,"") | X14: =IF($F14="Expm",$D14,"") | Y14: =Y13+SUM(G14:K14)-SUM(L14:X14) -> 0
E15: Choose Account | F15: =IF($E15=Categories!$A$1,"",IF($E15=Categories!$A$2,Categories!$B$2,IF($E15=Categories!$A$3,Categories!$B$3,IF($E15=Categories!$A$4,Categories!$B$4,IF($E15=Categories!$A$5,Categories!$B$5,IF($E15=Categories!$A$6,Categories!$B$6,IF($E15=Categories!$A$7,Categories!$B$7,IF($E15=Categories!$A$8,Categories!$B$8,IF($E15=Categories!$A$9,Categories!$B$9,IF($E15=Categories!$A$10,Categories!$B$10,IF($E15=Categories!$A$11,Categories!$B$11,IF($E15=Categories!$A$12,Categories!$B$12,IF($E15=Categories!$A$13,Categories!$B$13,IF($E15=Categories!$A$14,Categories!$B$14,IF($E15=Categories!$A$15,Categories!$B$15,IF($E15=Categories!$A$16,Categories!$B$16,IF($E15=Categories!$A$17,Categories!$B$17,IF($E15=Categories!$A$18,Categories!$B$18,IF($E15=Categories!$A$19,Categories!$B$19))))))))))))))))))) -> FALSE | G15: =IF($F15="Inc1",$D15,"") | H15: =IF($F15="Inc2",$D15,"") | I15: =IF($F15="Int",$D15,"") | J15: =IF($F15="Inc4",$D15,"") | K15: =IF($F15="Inc5",$D15,"") | L15: =IF($F15="ExpA",$D15,"") | M15: =IF($F15="ExpB",$D15,"") | N15: =IF($F15="ExpC",$D15,"") | O15: =IF($F15="ExpD",$D15,"") | P15: =IF($F15="ExpE",$D15,"") | Q15: =IF($F15="ExpF",$D15,"") | R15: =IF($F15="ExpG",$D15,"") | S15: =IF($F15="ExpH",$D15,"") | T15: =IF($F15="ExpI",$D15,"") | U15: =IF($F15="ExpJ",$D15,"") | V15: =IF($F15="ExpK",$D15,"") | W15: =IF($F15="ExpL",$D15,"") | X15: =IF($F15="Expm",$D15,"") | Y15: =Y14+SUM(G15:K15)-SUM(L15:X15) -> 0
E16: Choose Account | F16: =IF($E16=Categories!$A$1,"",IF($E16=Categories!$A$2,Categories!$B$2,IF($E16=Categories!$A$3,Categories!$B$3,IF($E16=Categories!$A$4,Categories!$B$4,IF($E16=Categories!$A$5,Categories!$B$5,IF($E16=Categories!$A$6,Categories!$B$6,IF($E16=Categories!$A$7,Categories!$B$7,IF($E16=Categories!$A$8,Categories!$B$8,IF($E16=Categories!$A$9,Categories!$B$9,IF($E16=Categories!$A$10,Categories!$B$10,IF($E16=Categories!$A$11,Categories!$B$11,IF($E16=Categories!$A$12,Categories!$B$12,IF($E16=Categories!$A$13,Categories!$B$13,IF($E16=Categories!$A$14,Categories!$B$14,IF($E16=Categories!$A$15,Categories!$B$15,IF($E16=Categories!$A$16,Categories!$B$16,IF($E16=Categories!$A$17,Categories!$B$17,IF($E16=Categories!$A$18,Categories!$B$18,IF($E16=Categories!$A$19,Categories!$B$19))))))))))))))))))) -> FALSE | G16: =IF($F16="Inc1",$D16,"") | H16: =IF($F16="Inc2",$D16,"") | I16: =IF($F16="Int",$D16,"") | J16: =IF($F16="Inc4",$D16,"") | K16: =IF($F16="Inc5",$D16,"") | L16: =IF($F16="ExpA",$D16,"") | M16: =IF($F16="ExpB",$D16,"") | N16: =IF($F16="ExpC",$D16,"") | O16: =IF($F16="ExpD",$D16,"") | P16: =IF($F16="ExpE",$D16,"") | Q16: =IF($F16="ExpF",$D16,"") | R16: =IF($F16="ExpG",$D16,"") | S16: =IF($F16="ExpH",$D16,"") | T16: =IF($F16="ExpI",$D16,"") | U16: =IF($F16="ExpJ",$D16,"") | V16: =IF($F16="ExpK",$D16,"") | W16: =IF($F16="ExpL",$D16,"") | X16: =IF($F16="Expm",$D16,"") | Y16: =Y15+SUM(G16:K16)-SUM(L16:X16) -> 0
E17: Choose Account | F17: =IF($E17=Categories!$A$1,"",IF($E17=Categories!$A$2,Categories!$B$2,IF($E17=Categories!$A$3,Categories!$B$3,IF($E17=Categories!$A$4,Categories!$B$4,IF($E17=Categories!$A$5,Categories!$B$5,IF($E17=Categories!$A$6,Categories!$B$6,IF($E17=Categories!$A$7,Categories!$B$7,IF($E17=Categories!$A$8,Categories!$B$8,IF($E17=Categories!$A$9,Categories!$B$9,IF($E17=Categories!$A$10,Categories!$B$10,IF($E17=Categories!$A$11,Categories!$B$11,IF($E17=Categories!$A$12,Categories!$B$12,IF($E17=Categories!$A$13,Categories!$B$13,IF($E17=Categories!$A$14,Categories!$B$14,IF($E17=Categories!$A$15,Categories!$B$15,IF($E17=Categories!$A$16,Categories!$B$16,IF($E17=Categories!$A$17,Categories!$B$17,IF($E17=Categories!$A$18,Categories!$B$18,IF($E17=Categories!$A$19,Categories!$B$19))))))))))))))))))) -> FALSE | G17: =IF($F17="Inc1",$D17,"") | H17: =IF($F17="Inc2",$D17,"") | I17: =IF($F17="Int",$D17,"") | J17: =IF($F17="Inc4",$D17,"") | K17: =IF($F17="Inc5",$D17,"") | L17: =IF($F17="ExpA",$D17,"") | M17: =IF($F17="ExpB",$D17,"") | N17: =IF($F17="ExpC",$D17,"") | O17: =IF($F17="ExpD",$D17,"") | P17: =IF($F17="ExpE",$D17,"") | Q17: =IF($F17="ExpF",$D17,"") | R17: =IF($F17="ExpG",$D17,"") | S17: =IF($F17="ExpH",$D17,"") | T17: =IF($F17="ExpI",$D17,"") | U17: =IF($F17="ExpJ",$D17,"") | V17: =IF($F17="ExpK",$D17,"") | W17: =IF($F17="ExpL",$D17,"") | X17: =IF($F17="Expm",$D17,"") | Y17: =Y16+SUM(G17:K17)-SUM(L17:X17) -> 0
E18: Choose Account | F18: =IF($E18=Categories!$A$1,"",IF($E18=Categories!$A$2,Categories!$B$2,IF($E18=Categories!$A$3,Categories!$B$3,IF($E18=Categories!$A$4,Categories!$B$4,IF($E18=Categories!$A$5,Categories!$B$5,IF($E18=Categories!$A$6,Categories!$B$6,IF($E18=Categories!$A$7,Categories!$B$7,IF($E18=Categories!$A$8,Categories!$B$8,IF($E18=Categories!$A$9,Categories!$B$9,IF($E18=Categories!$A$10,Categories!$B$10,IF($E18=Categories!$A$11,Categories!$B$11,IF($E18=Categories!$A$12,Categories!$B$12,IF($E18=Categories!$A$13,Categories!$B$13,IF($E18=Categories!$A$14,Categories!$B$14,IF($E18=Categories!$A$15,Categories!$B$15,IF($E18=Categories!$A$16,Categories!$B$16,IF($E18=Categories!$A$17,Categories!$B$17,IF($E18=Categories!$A$18,Categories!$B$18,IF($E18=Categories!$A$19,Categories!$B$19))))))))))))))))))) -> FALSE | G18: =IF($F18="Inc1",$D18,"") | H18: =IF($F18="Inc2",$D18,"") | I18: =IF($F18="Int",$D18,"") | J18: =IF($F18="Inc4",$D18,"") | K18: =IF($F18="Inc5",$D18,"") | L18: =IF($F18="ExpA",$D18,"") | M18: =IF($F18="ExpB",$D18,"") | N18: =IF($F18="ExpC",$D18,"") | O18: =IF($F18="ExpD",$D18,"") | P18: =IF($F18="ExpE",$D18,"") | Q18: =IF($F18="ExpF",$D18,"") | R18: =IF($F18="ExpG",$D18,"") | S18: =IF($F18="ExpH",$D18,"") | T18: =IF($F18="ExpI",$D18,"") | U18: =IF($F18="ExpJ",$D18,"") | V18: =IF($F18="ExpK",$D18,"") | W18: =IF($F18="ExpL",$D18,"") | X18: =IF($F18="Expm",$D18,"") | Y18: =Y17+SUM(G18:K18)-SUM(L18:X18) -> 0
... E95: Choose Account | F95: =IF($E95=Categories!$A$1,"",IF($E95=Categories!$A$2,Categories!$B$2,IF($E95=Categories!$A$3,Categories!$B$3,IF($E95=Categories!$A$4,Categories!$B$4,IF($E95=Categories!$A$5,Categories!$B$5,IF($E95=Categories!$A$6,Categories!$B$6,IF($E95=Categories!$A$7,Categories!$B$7,IF($E95=Categories!$A$8,Categories!$B$8,IF($E95=Categories!$A$9,Categories!$B$9,IF($E95=Categories!$A$10,Categories!$B$10,IF($E95=Categories!$A$11,Categories!$B$11,IF($E95=Categories!$A$12,Categories!$B$12,IF($E95=Categories!$A$13,Categories!$B$13,IF($E95=Categories!$A$14,Categories!$B$14,IF($E95=Categories!$A$15,Categories!$B$15,IF($E95=Categories!$A$16,Categories!$B$16,IF($E95=Categories!$A$17,Categories!$B$17,IF($E95=Categories!$A$18,Categories!$B$18,IF($E95=Categories!$A$19,Categories!$B$19))))))))))))))))))) -> FALSE | G95: =IF($F95="Inc1",$D95,"") | H95: =IF($F95="Inc2",$D95,"") | I95: =IF($F95="Int",$D95,"") | J95: =IF($F95="Inc4",$D95,"") | K95: =IF($F95="Inc5",$D95,"") | L95: =IF($F95="ExpA",$D95,"") | M95: =IF($F95="ExpB",$D95,"") | N95: =IF($F95="ExpC",$D95,"") | O95: =IF($F95="ExpD",$D95,"") | P95: =IF($F95="ExpE",$D95,"") | Q95: =IF($F95="ExpF",$D95,"") | R95: =IF($F95="ExpG",$D95,"") | S95: =IF($F95="ExpH",$D95,"") | T95: =IF($F95="ExpI",$D95,"") | U95: =IF($F95="ExpJ",$D95,"") | V95: =IF($F95="ExpK",$D95,"") | W95: =IF($F95="ExpL",$D95,"") | X95: =IF($F95="Expm",$D95,"") | Y95: =Y94+SUM(G95:K95)-SUM(L95:X95) -> 0
B96: Total | G96: =SUM(G6:G95) -> 0 | H96: =SUM(H6:H95) -> 0 | I96: =SUM(I6:I95) -> 0 | J96: =SUM(J6:J95) -> 0 | K96: =SUM(K6:K95) -> 0 | L96: =SUM(L6:L95) -> 0 | M96: =SUM(M6:M95) -> 0 | N96: =SUM(N6:N95) -> 0 | ... X96: =SUM(X6:X95) -> 0

Sheet May
A1: Cash Book May | D1: =Instructions!C3 -> Lucy's Tailored Tails
R3: Bank balance B/f | Y3: =IF(Instructions!C7="May",Instructions!C6,Apr!Y95) -> 0
A4: UPDATE THESE COLUMNS ONLY | G4: Income | L4: Expenditure
A5: Date | B5: Customer or Supplier | C5: Reference | D5: Amount | E5: Category | G5: =Categories!A2 -> Shop Sales | H5: =Categories!A3 -> Income 2 | I5: =Categories!A4 -> Income 3 | J5: =Categories!A5 -> Income 4 | K5: =Categories!A6 -> Income 5 | L5: =Categories!A7 -> Website Fees | M5: =Categories!A8 -> Exp 2 | N5: =Categories!A9 -> Exp 3 | O5: =Categories!A10 -> Exp 4 | P5: =Categories!A11 -> Exp 5 | Q5: =Categories!A12 -> Exp 6 | R5: =Categories!A13 -> Exp 7 | S5: =Categories!A14 -> Exp 8 | T5: =Categories!A15 -> Exp 9 | U5: =Categories!A16 -> Exp 10 | V5: =Categories!A17 -> Exp 11 | W5: =Categories!A18 -> Exp 12 | X5: =Categories!A19 -> Exp 13 | Y5: Balance
E6: Choose Account | F6: =IF($E6=Categories!$A$1,"",IF($E6=Categories!$A$2,Categories!$B$2,IF($E6=Categories!$A$3,Categories!$B$3,IF($E6=Categories!$A$4,Categories!$B$4,IF($E6=Categories!$A$5,Categories!$B$5,IF($E6=Categories!$A$6,Categories!$B$6,IF($E6=Categories!$A$7,Categories!$B$7,IF($E6=Categories!$A$8,Categories!$B$8,IF($E6=Categories!$A$9,Categories!$B$9,IF($E6=Categories!$A$10,Categories!$B$10,IF($E6=Categories!$A$11,Categories!$B$11,IF($E6=Categories!$A$12,Categories!$B$12,IF($E6=Categories!$A$13,Categories!$B$13,IF($E6=Categories!$A$14,Categories!$B$14,IF($E6=Categories!$A$15,Categories!$B$15,IF($E6=Categories!$A$16,Categories!$B$16,IF($E6=Categories!$A$17,Categories!$B$17,IF($E6=Categories!$A$18,Categories!$B$18,IF($E6=Categories!$A$19,Categories!$B$19))))))))))))))))))) -> FALSE | G6: =IF($F6="Inc1",$D6,"") | H6: =IF($F6="Inc2",$D6,"") | I6: =IF($F6="Int",$D6,"") | J6: =IF($F6="Inc4",$D6,"") | K6: =IF($F6="Inc5",$D6,"") | L6: =IF($F6="ExpA",$D6,"") | M6: =IF($F6="ExpB",$D6,"") | N6: =IF($F6="ExpC",$D6,"") | O6: =IF($F6="ExpD",$D6,"") | P6: =IF($F6="ExpE",$D6,"") | Q6: =IF($F6="ExpF",$D6,"") | R6: =IF($F6="ExpG",$D6,"") | S6: =IF($F6="ExpH",$D6,"") | T6: =IF($F6="ExpI",$D6,"") | U6: =IF($F6="ExpJ",$D6,"") | V6: =IF($F6="ExpK",$D6,"") | W6: =IF($F6="ExpL",$D6,"") | X6: =IF($F6="Expm",$D6,"") | Y6: =$Y$3+SUM(G6:K6)-SUM(L6:X6) -> 0
E7: Choose Account | F7: =IF($E7=Categories!$A$1,"",IF($E7=Categories!$A$2,Categories!$B$2,IF($E7=Categories!$A$3,Categories!$B$3,IF($E7=Categories!$A$4,Categories!$B$4,IF($E7=Categories!$A$5,Categories!$B$5,IF($E7=Categories!$A$6,Categories!$B$6,IF($E7=Categories!$A$7,Categories!$B$7,IF($E7=Categories!$A$8,Categories!$B$8,IF($E7=Categories!$A$9,Categories!$B$9,IF($E7=Categories!$A$10,Categories!$B$10,IF($E7=Categories!$A$11,Categories!$B$11,IF($E7=Categories!$A$12,Categories!$B$12,IF($E7=Categories!$A$13,Categories!$B$13,IF($E7=Categories!$A$14,Categories!$B$14,IF($E7=Categories!$A$15,Categories!$B$15,IF($E7=Categories!$A$16,Categories!$B$16,IF($E7=Categories!$A$17,Categories!$B$17,IF($E7=Categories!$A$18,Categories!$B$18,IF($E7=Categories!$A$19,Categories!$B$19))))))))))))))))))) -> FALSE | G7: =IF($F7="Inc1",$D7,"") | H7: =IF($F7="Inc2",$D7,"") | I7: =IF($F7="Int",$D7,"") | J7: =IF($F7="Inc4",$D7,"") | K7: =IF($F7="Inc5",$D7,"") | L7: =IF($F7="ExpA",$D7,"") | M7: =IF($F7="ExpB",$D7,"") | N7: =IF($F7="ExpC",$D7,"") | O7: =IF($F7="ExpD",$D7,"") | P7: =IF($F7="ExpE",$D7,"") | Q7: =IF($F7="ExpF",$D7,"") | R7: =IF($F7="ExpG",$D7,"") | S7: =IF($F7="ExpH",$D7,"") | T7: =IF($F7="ExpI",$D7,"") | U7: =IF($F7="ExpJ",$D7,"") | V7: =IF($F7="ExpK",$D7,"") | W7: =IF($F7="ExpL",$D7,"") | X7: =IF($F7="Expm",$D7,"") | Y7: =Y6+SUM(G7:K7)-SUM(L7:X7) -> 0
E8: Choose Account | F8: =IF($E8=Categories!$A$1,"",IF($E8=Categories!$A$2,Categories!$B$2,IF($E8=Categories!$A$3,Categories!$B$3,IF($E8=Categories!$A$4,Categories!$B$4,IF($E8=Categories!$A$5,Categories!$B$5,IF($E8=Categories!$A$6,Categories!$B$6,IF($E8=Categories!$A$7,Categories!$B$7,IF($E8=Categories!$A$8,Categories!$B$8,IF($E8=Categories!$A$9,Categories!$B$9,IF($E8=Categories!$A$10,Categories!$B$10,IF($E8=Categories!$A$11,Categories!$B$11,IF($E8=Categories!$A$12,Categories!$B$12,IF($E8=Categories!$A$13,Categories!$B$13,IF($E8=Categories!$A$14,Categories!$B$14,IF($E8=Categories!$A$15,Categories!$B$15,IF($E8=Categories!$A$16,Categories!$B$16,IF($E8=Categories!$A$17,Categories!$B$17,IF($E8=Categories!$A$18,Categories!$B$18,IF($E8=Categories!$A$19,Categories!$B$19))))))))))))))))))) -> FALSE | G8: =IF($F8="Inc1",$D8,"") | H8: =IF($F8="Inc2",$D8,"") | I8: =IF($F8="Int",$D8,"") | J8: =IF($F8="Inc4",$D8,"") | K8: =IF($F8="Inc5",$D8,"") | L8: =IF($F8="ExpA",$D8,"") | M8: =IF($F8="ExpB",$D8,"") | N8: =IF($F8="ExpC",$D8,"") | O8: =IF($F8="ExpD",$D8,"") | P8: =IF($F8="ExpE",$D8,"") | Q8: =IF($F8="ExpF",$D8,"") | R8: =IF($F8="ExpG",$D8,"") | S8: =IF($F8="ExpH",$D8,"") | T8: =IF($F8="ExpI",$D8,"") | U8: =IF($F8="ExpJ",$D8,"") | V8: =IF($F8="ExpK",$D8,"") | W8: =IF($F8="ExpL",$D8,"") | X8: =IF($F8="Expm",$D8,"") | Y8: =Y7+SUM(G8:K8)-SUM(L8:X8) -> 0
E9: Choose Account | F9: =IF($E9=Categories!$A$1,"",IF($E9=Categories!$A$2,Categories!$B$2,IF($E9=Categories!$A$3,Categories!$B$3,IF($E9=Categories!$A$4,Categories!$B$4,IF($E9=Categories!$A$5,Categories!$B$5,IF($E9=Categories!$A$6,Categories!$B$6,IF($E9=Categories!$A$7,Categories!$B$7,IF($E9=Categories!$A$8,Categories!$B$8,IF($E9=Categories!$A$9,Categories!$B$9,IF($E9=Categories!$A$10,Categories!$B$10,IF($E9=Categories!$A$11,Categories!$B$11,IF($E9=Categories!$A$12,Categories!$B$12,IF($E9=Categories!$A$13,Categories!$B$13,IF($E9=Categories!$A$14,Categories!$B$14,IF($E9=Categories!$A$15,Categories!$B$15,IF($E9=Categories!$A$16,Categories!$B$16,IF($E9=Categories!$A$17,Categories!$B$17,IF($E9=Categories!$A$18,Categories!$B$18,IF($E9=Categories!$A$19,Categories!$B$19))))))))))))))))))) -> FALSE | G9: =IF($F9="Inc1",$D9,"") | H9: =IF($F9="Inc2",$D9,"") | I9: =IF($F9="Int",$D9,"") | J9: =IF($F9="Inc4",$D9,"") | K9: =IF($F9="Inc5",$D9,"") | L9: =IF($F9="ExpA",$D9,"") | M9: =IF($F9="ExpB",$D9,"") | N9: =IF($F9="ExpC",$D9,"") | O9: =IF($F9="ExpD",$D9,"") | P9: =IF($F9="ExpE",$D9,"") | Q9: =IF($F9="ExpF",$D9,"") | R9: =IF($F9="ExpG",$D9,"") | S9: =IF($F9="ExpH",$D9,"") | T9: =IF($F9="ExpI",$D9,"") | U9: =IF($F9="ExpJ",$D9,"") | V9: =IF($F9="ExpK",$D9,"") | W9: =IF($F9="ExpL",$D9,"") | X9: =IF($F9="Expm",$D9,"") | Y9: =Y8+SUM(G9:K9)-SUM(L9:X9) -> 0
E10: Choose Account | F10: =IF($E10=Categories!$A$1,"",IF($E10=Categories!$A$2,Categories!$B$2,IF($E10=Categories!$A$3,Categories!$B$3,IF($E10=Categories!$A$4,Categories!$B$4,IF($E10=Categories!$A$5,Categories!$B$5,IF($E10=Categories!$A$6,Categories!$B$6,IF($E10=Categories!$A$7,Categories!$B$7,IF($E10=Categories!$A$8,Categories!$B$8,IF($E10=Categories!$A$9,Categories!$B$9,IF($E10=Categories!$A$10,Categories!$B$10,IF($E10=Categories!$A$11,Categories!$B$11,IF($E10=Categories!$A$12,Categories!$B$12,IF($E10=Categories!$A$13,Categories!$B$13,IF($E10=Categories!$A$14,Categories!$B$14,IF($E10=Categories!$A$15,Categories!$B$15,IF($E10=Categories!$A$16,Categories!$B$16,IF($E10=Categories!$A$17,Categories!$B$17,IF($E10=Categories!$A$18,Categories!$B$18,IF($E10=Categories!$A$19,Categories!$B$19))))))))))))))))))) -> FALSE | G10: =IF($F10="Inc1",$D10,"") | H10: =IF($F10="Inc2",$D10,"") | I10: =IF($F10="Int",$D10,"") | J10: =IF($F10="Inc4",$D10,"") | K10: =IF($F10="Inc5",$D10,"") | L10: =IF($F10="ExpA",$D10,"") | M10: =IF($F10="ExpB",$D10,"") | N10: =IF($F10="ExpC",$D10,"") | O10: =IF($F10="ExpD",$D10,"") | P10: =IF($F10="ExpE",$D10,"") | Q10: =IF($F10="ExpF",$D10,"") | R10: =IF($F10="ExpG",$D10,"") | S10: =IF($F10="ExpH",$D10,"") | T10: =IF($F10="ExpI",$D10,"") | U10: =IF($F10="ExpJ",$D10,"") | V10: =IF($F10="ExpK",$D10,"") | W10: =IF($F10="ExpL",$D10,"") | X10: =IF($F10="Expm",$D10,"") | Y10: =Y9+SUM(G10:K10)-SUM(L10:X10) -> 0
E11: Choose Account | F11: =IF($E11=Categories!$A$1,"",IF($E11=Categories!$A$2,Categories!$B$2,IF($E11=Categories!$A$3,Categories!$B$3,IF($E11=Categories!$A$4,Categories!$B$4,IF($E11=Categories!$A$5,Categories!$B$5,IF($E11=Categories!$A$6,Categories!$B$6,IF($E11=Categories!$A$7,Categories!$B$7,IF($E11=Categories!$A$8,Categories!$B$8,IF($E11=Categories!$A$9,Categories!$B$9,IF($E11=Categories!$A$10,Categories!$B$10,IF($E11=Categories!$A$11,Categories!$B$11,IF($E11=Categories!$A$12,Categories!$B$12,IF($E11=Categories!$A$13,Categories!$B$13,IF($E11=Categories!$A$14,Categories!$B$14,IF($E11=Categories!$A$15,Categories!$B$15,IF($E11=Categories!$A$16,Categories!$B$16,IF($E11=Categories!$A$17,Categories!$B$17,IF($E11=Categories!$A$18,Categories!$B$18,IF($E11=Categories!$A$19,Categories!$B$19))))))))))))))))))) -> FALSE | G11: =IF($F11="Inc1",$D11,"") | H11: =IF($F11="Inc2",$D11,"") | I11: =IF($F11="Int",$D11,"") | J11: =IF($F11="Inc4",$D11,"") | K11: =IF($F11="Inc5",$D11,"") | L11: =IF($F11="ExpA",$D11,"") | M11: =IF($F11="ExpB",$D11,"") | N11: =IF($F11="ExpC",$D11,"") | O11: =IF($F11="ExpD",$D11,"") | P11: =IF($F11="ExpE",$D11,"") | Q11: =IF($F11="ExpF",$D11,"") | R11: =IF($F11="ExpG",$D11,"") | S11: =IF($F11="ExpH",$D11,"") | T11: =IF($F11="ExpI",$D11,"") | U11: =IF($F11="ExpJ",$D11,"") | V11: =IF($F11="ExpK",$D11,"") | W11: =IF($F11="ExpL",$D11,"") | X11: =IF($F11="Expm",$D11,"") | Y11: =Y10+SUM(G11:K11)-SUM(L11:X11) -> 0
E12: Choose Account | F12: =IF($E12=Categories!$A$1,"",IF($E12=Categories!$A$2,Categories!$B$2,IF($E12=Categories!$A$3,Categories!$B$3,IF($E12=Categories!$A$4,Categories!$B$4,IF($E12=Categories!$A$5,Categories!$B$5,IF($E12=Categories!$A$6,Categories!$B$6,IF($E12=Categories!$A$7,Categories!$B$7,IF($E12=Categories!$A$8,Categories!$B$8,IF($E12=Categories!$A$9,Categories!$B$9,IF($E12=Categories!$A$10,Categories!$B$10,IF($E12=Categories!$A$11,Categories!$B$11,IF($E12=Categories!$A$12,Categories!$B$12,IF($E12=Categories!$A$13,Categories!$B$13,IF($E12=Categories!$A$14,Categories!$B$14,IF($E12=Categories!$A$15,Categories!$B$15,IF($E12=Categories!$A$16,Categories!$B$16,IF($E12=Categories!$A$17,Categories!$B$17,IF($E12=Categories!$A$18,Categories!$B$18,IF($E12=Categories!$A$19,Categories!$B$19))))))))))))))))))) -> FALSE | G12: =IF($F12="Inc1",$D12,"") | H12: =IF($F12="Inc2",$D12,"") | I12: =IF($F12="Int",$D12,"") | J12: =IF($F12="Inc4",$D12,"") | K12: =IF($F12="Inc5",$D12,"") | L12: =IF($F12="ExpA",$D12,"") | M12: =IF($F12="ExpB",$D12,"") | N12: =IF($F12="ExpC",$D12,"") | O12: =IF($F12="ExpD",$D12,"") | P12: =IF($F12="ExpE",$D12,"") | Q12: =IF($F12="ExpF",$D12,"") | R12: =IF($F12="ExpG",$D12,"") | S12: =IF($F12="ExpH",$D12,"") | T12: =IF($F12="ExpI",$D12,"") | U12: =IF($F12="ExpJ",$D12,"") | V12: =IF($F12="ExpK",$D12,"") | W12: =IF($F12="ExpL",$D12,"") | X12: =IF($F12="Expm",$D12,"") | Y12: =Y11+SUM(G12:K12)-SUM(L12:X12) -> 0
E13: Choose Account | F13: =IF($E13=Categories!$A$1,"",IF($E13=Categories!$A$2,Categories!$B$2,IF($E13=Categories!$A$3,Categories!$B$3,IF($E13=Categories!$A$4,Categories!$B$4,IF($E13=Categories!$A$5,Categories!$B$5,IF($E13=Categories!$A$6,Categories!$B$6,IF($E13=Categories!$A$7,Categories!$B$7,IF($E13=Categories!$A$8,Categories!$B$8,IF($E13=Categories!$A$9,Categories!$B$9,IF($E13=Categories!$A$10,Categories!$B$10,IF($E13=Categories!$A$11,Categories!$B$11,IF($E13=Categories!$A$12,Categories!$B$12,IF($E13=Categories!$A$13,Categories!$B$13,IF($E13=Categories!$A$14,Categories!$B$14,IF($E13=Categories!$A$15,Categories!$B$15,IF($E13=Categories!$A$16,Categories!$B$16,IF($E13=Categories!$A$17,Categories!$B$17,IF($E13=Categories!$A$18,Categories!$B$18,IF($E13=Categories!$A$19,Categories!$B$19))))))))))))))))))) -> FALSE | G13: =IF($F13="Inc1",$D13,"") | H13: =IF($F13="Inc2",$D13,"") | I13: =IF($F13="Int",$D13,"") | J13: =IF($F13="Inc4",$D13,"") | K13: =IF($F13="Inc5",$D13,"") | L13: =IF($F13="ExpA",$D13,"") | M13: =IF($F13="ExpB",$D13,"") | N13: =IF($F13="ExpC",$D13,"") | O13: =IF($F13="ExpD",$D13,"") | P13: =IF($F13="ExpE",$D13,"") | Q13: =IF($F13="ExpF",$D13,"") | R13: =IF($F13="ExpG",$D13,"") | S13: =IF($F13="ExpH",$D13,"") | T13: =IF($F13="ExpI",$D13,"") | U13: =IF($F13="ExpJ",$D13,"") | V13: =IF($F13="ExpK",$D13,"") | W13: =IF($F13="ExpL",$D13,"") | X13: =IF($F13="Expm",$D13,"") | Y13: =Y12+SUM(G13:K13)-SUM(L13:X13) -> 0
E14: Choose Account | F14: =IF($E14=Categories!$A$1,"",IF($E14=Categories!$A$2,Categories!$B$2,IF($E14=Categories!$A$3,Categories!$B$3,IF($E14=Categories!$A$4,Categories!$B$4,IF($E14=Categories!$A$5,Categories!$B$5,IF($E14=Categories!$A$6,Categories!$B$6,IF($E14=Categories!$A$7,Categories!$B$7,IF($E14=Categories!$A$8,Categories!$B$8,IF($E14=Categories!$A$9,Categories!$B$9,IF($E14=Categories!$A$10,Categories!$B$10,IF($E14=Categories!$A$11,Categories!$B$11,IF($E14=Categories!$A$12,Categories!$B$12,IF($E14=Categories!$A$13,Categories!$B$13,IF($E14=Categories!$A$14,Categories!$B$14,IF($E14=Categories!$A$15,Categories!$B$15,IF($E14=Categories!$A$16,Categories!$B$16,IF($E14=Categories!$A$17,Categories!$B$17,IF($E14=Categories!$A$18,Categories!$B$18,IF($E14=Categories!$A$19,Categories!$B$19))))))))))))))))))) -> FALSE | G14: =IF($F14="Inc1",$D14,"") | H14: =IF($F14="Inc2",$D14,"") | I14: =IF($F14="Int",$D14,"") | J14: =IF($F14="Inc4",$D14,"") | K14: =IF($F14="Inc5",$D14,"") | L14: =IF($F14="ExpA",$D14,"") | M14: =IF($F14="ExpB",$D14,"") | N14: =IF($F14="ExpC",$D14,"") | O14: =IF($F14="ExpD",$D14,"") | P14: =IF($F14="ExpE",$D14,"") | Q14: =IF($F14="ExpF",$D14,"") | R14: =IF($F14="ExpG",$D14,"") | S14: =IF($F14="ExpH",$D14,"") | T14: =IF($F14="ExpI",$D14,"") | U14: =IF($F14="ExpJ",$D14,"") | V14: =IF($F14="ExpK",$D14,"") | W14: =IF($F14="ExpL",$D14,"") | X14: =IF($F14="Expm",$D14,"") | Y14: =Y13+SUM(G14:K14)-SUM(L14:X14) -> 0
E15: Choose Account | F15: =IF($E15=Categories!$A$1,"",IF($E15=Categories!$A$2,Categories!$B$2,IF($E15=Categories!$A$3,Categories!$B$3,IF($E15=Categories!$A$4,Categories!$B$4,IF($E15=Categories!$A$5,Categories!$B$5,IF($E15=Categories!$A$6,Categories!$B$6,IF($E15=Categories!$A$7,Categories!$B$7,IF($E15=Categories!$A$8,Categories!$B$8,IF($E15=Categories!$A$9,Categories!$B$9,IF($E15=Categories!$A$10,Categories!$B$10,IF($E15=Categories!$A$11,Categories!$B$11,IF($E15=Categories!$A$12,Categories!$B$12,IF($E15=Categories!$A$13,Categories!$B$13,IF($E15=Categories!$A$14,Categories!$B$14,IF($E15=Categories!$A$15,Categories!$B$15,IF($E15=Categories!$A$16,Categories!$B$16,IF($E15=Categories!$A$17,Categories!$B$17,IF($E15=Categories!$A$18,Categories!$B$18,IF($E15=Categories!$A$19,Categories!$B$19))))))))))))))))))) -> FALSE | G15: =IF($F15="Inc1",$D15,"") | H15: =IF($F15="Inc2",$D15,"") | I15: =IF($F15="Int",$D15,"") | J15: =IF($F15="Inc4",$D15,"") | K15: =IF($F15="Inc5",$D15,"") | L15: =IF($F15="ExpA",$D15,"") | M15: =IF($F15="ExpB",$D15,"") | N15: =IF($F15="ExpC",$D15,"") | O15: =IF($F15="ExpD",$D15,"") | P15: =IF($F15="ExpE",$D15,"") | Q15: =IF($F15="ExpF",$D15,"") | R15: =IF($F15="ExpG",$D15,"") | S15: =IF($F15="ExpH",$D15,"") | T15: =IF($F15="ExpI",$D15,"") | U15: =IF($F15="ExpJ",$D15,"") | V15: =IF($F15="ExpK",$D15,"") | W15: =IF($F15="ExpL",$D15,"") | X15: =IF($F15="Expm",$D15,"") | Y15: =Y14+SUM(G15:K15)-SUM(L15:X15) -> 0
E16: Choose Account | F16: =IF($E16=Categories!$A$1,"",IF($E16=Categories!$A$2,Categories!$B$2,IF($E16=Categories!$A$3,Categories!$B$3,IF($E16=Categories!$A$4,Categories!$B$4,IF($E16=Categories!$A$5,Categories!$B$5,IF($E16=Categories!$A$6,Categories!$B$6,IF($E16=Categories!$A$7,Categories!$B$7,IF($E16=Categories!$A$8,Categories!$B$8,IF($E16=Categories!$A$9,Categories!$B$9,IF($E16=Categories!$A$10,Categories!$B$10,IF($E16=Categories!$A$11,Categories!$B$11,IF($E16=Categories!$A$12,Categories!$B$12,IF($E16=Categories!$A$13,Categories!$B$13,IF($E16=Categories!$A$14,Categories!$B$14,IF($E16=Categories!$A$15,Categories!$B$15,IF($E16=Categories!$A$16,Categories!$B$16,IF($E16=Categories!$A$17,Categories!$B$17,IF($E16=Categories!$A$18,Categories!$B$18,IF($E16=Categories!$A$19,Categories!$B$19))))))))))))))))))) -> FALSE | G16: =IF($F16="Inc1",$D16,"") | H16: =IF($F16="Inc2",$D16,"") | I16: =IF($F16="Int",$D16,"") | J16: =IF($F16="Inc4",$D16,"") | K16: =IF($F16="Inc5",$D16,"") | L16: =IF($F16="ExpA",$D16,"") | M16: =IF($F16="ExpB",$D16,"") | N16: =IF($F16="ExpC",$D16,"") | O16: =IF($F16="ExpD",$D16,"") | P16: =IF($F16="ExpE",$D16,"") | Q16: =IF($F16="ExpF",$D16,"") | R16: =IF($F16="ExpG",$D16,"") | S16: =IF($F16="ExpH",$D16,"") | T16: =IF($F16="ExpI",$D16,"") | U16: =IF($F16="ExpJ",$D16,"") | V16: =IF($F16="ExpK",$D16,"") | W16: =IF($F16="ExpL",$D16,"") | X16: =IF($F16="Expm",$D16,"") | Y16: =Y15+SUM(G16:K16)-SUM(L16:X16) -> 0
E17: Choose Account | F17: =IF($E17=Categories!$A$1,"",IF($E17=Categories!$A$2,Categories!$B$2,IF($E17=Categories!$A$3,Categories!$B$3,IF($E17=Categories!$A$4,Categories!$B$4,IF($E17=Categories!$A$5,Categories!$B$5,IF($E17=Categories!$A$6,Categories!$B$6,IF($E17=Categories!$A$7,Categories!$B$7,IF($E17=Categories!$A$8,Categories!$B$8,IF($E17=Categories!$A$9,Categories!$B$9,IF($E17=Categories!$A$10,Categories!$B$10,IF($E17=Categories!$A$11,Categories!$B$11,IF($E17=Categories!$A$12,Categories!$B$12,IF($E17=Categories!$A$13,Categories!$B$13,IF($E17=Categories!$A$14,Categories!$B$14,IF($E17=Categories!$A$15,Categories!$B$15,IF($E17=Categories!$A$16,Categories!$B$16,IF($E17=Categories!$A$17,Categories!$B$17,IF($E17=Categories!$A$18,Categories!$B$18,IF($E17=Categories!$A$19,Categories!$B$19))))))))))))))))))) -> FALSE | G17: =IF($F17="Inc1",$D17,"") | H17: =IF($F17="Inc2",$D17,"") | I17: =IF($F17="Int",$D17,"") | J17: =IF($F17="Inc4",$D17,"") | K17: =IF($F17="Inc5",$D17,"") | L17: =IF($F17="ExpA",$D17,"") | M17: =IF($F17="ExpB",$D17,"") | N17: =IF($F17="ExpC",$D17,"") | O17: =IF($F17="ExpD",$D17,"") | P17: =IF($F17="ExpE",$D17,"") | Q17: =IF($F17="ExpF",$D17,"") | R17: =IF($F17="ExpG",$D17,"") | S17: =IF($F17="ExpH",$D17,"") | T17: =IF($F17="ExpI",$D17,"") | U17: =IF($F17="ExpJ",$D17,"") | V17: =IF($F17="ExpK",$D17,"") | W17: =IF($F17="ExpL",$D17,"") | X17: =IF($F17="Expm",$D17,"") | Y17: =Y16+SUM(G17:K17)-SUM(L17:X17) -> 0
E18: Choose Account | F18: =IF($E18=Categories!$A$1,"",IF($E18=Categories!$A$2,Categories!$B$2,IF($E18=Categories!$A$3,Categories!$B$3,IF($E18=Categories!$A$4,Categories!$B$4,IF($E18=Categories!$A$5,Categories!$B$5,IF($E18=Categories!$A$6,Categories!$B$6,IF($E18=Categories!$A$7,Categories!$B$7,IF($E18=Categories!$A$8,Categories!$B$8,IF($E18=Categories!$A$9,Categories!$B$9,IF($E18=Categories!$A$10,Categories!$B$10,IF($E18=Categories!$A$11,Categories!$B$11,IF($E18=Categories!$A$12,Categories!$B$12,IF($E18=Categories!$A$13,Categories!$B$13,IF($E18=Categories!$A$14,Categories!$B$14,IF($E18=Categories!$A$15,Categories!$B$15,IF($E18=Categories!$A$16,Categories!$B$16,IF($E18=Categories!$A$17,Categories!$B$17,IF($E18=Categories!$A$18,Categories!$B$18,IF($E18=Categories!$A$19,Categories!$B$19))))))))))))))))))) -> FALSE | G18: =IF($F18="Inc1",$D18,"") | H18: =IF($F18="Inc2",$D18,"") | I18: =IF($F18="Int",$D18,"") | J18: =IF($F18="Inc4",$D18,"") | K18: =IF($F18="Inc5",$D18,"") | L18: =IF($F18="ExpA",$D18,"") | M18: =IF($F18="ExpB",$D18,"") | N18: =IF($F18="ExpC",$D18,"") | O18: =IF($F18="ExpD",$D18,"") | P18: =IF($F18="ExpE",$D18,"") | Q18: =IF($F18="ExpF",$D18,"") | R18: =IF($F18="ExpG",$D18,"") | S18: =IF($F18="ExpH",$D18,"") | T18: =IF($F18="ExpI",$D18,"") | U18: =IF($F18="ExpJ",$D18,"") | V18: =IF($F18="ExpK",$D18,"") | W18: =IF($F18="ExpL",$D18,"") | X18: =IF($F18="Expm",$D18,"") | Y18: =Y17+SUM(G18:K18)-SUM(L18:X18) -> 0
... E95: Choose Account | F95: =IF($E95=Categories!$A$1,"",IF($E95=Categories!$A$2,Categories!$B$2,IF($E95=Categories!$A$3,Categories!$B$3,IF($E95=Categories!$A$4,Categories!$B$4,IF($E95=Categories!$A$5,Categories!$B$5,IF($E95=Categories!$A$6,Categories!$B$6,IF($E95=Categories!$A$7,Categories!$B$7,IF($E95=Categories!$A$8,Categories!$B$8,IF($E95=Categories!$A$9,Categories!$B$9,IF($E95=Categories!$A$10,Categories!$B$10,IF($E95=Categories!$A$11,Categories!$B$11,IF($E95=Categories!$A$12,Categories!$B$12,IF($E95=Categories!$A$13,Categories!$B$13,IF($E95=Categories!$A$14,Categories!$B$14,IF($E95=Categories!$A$15,Categories!$B$15,IF($E95=Categories!$A$16,Categories!$B$16,IF($E95=Categories!$A$17,Categories!$B$17,IF($E95=Categories!$A$18,Categories!$B$18,IF($E95=Categories!$A$19,Categories!$B$19))))))))))))))))))) -> FALSE | G95: =IF($F95="Inc1",$D95,"") | H95: =IF($F95="Inc2",$D95,"") | I95: =IF($F95="Int",$D95,"") | J95: =IF($F95="Inc4",$D95,"") | K95: =IF($F95="Inc5",$D95,"") | L95: =IF($F95="ExpA",$D95,"") | M95: =IF($F95="ExpB",$D95,"") | N95: =IF($F95="ExpC",$D95,"") | O95: =IF($F95="ExpD",$D95,"") | P95: =IF($F95="ExpE",$D95,"") | Q95: =IF($F95="ExpF",$D95,"") | R95: =IF($F95="ExpG",$D95,"") | S95: =IF($F95="ExpH",$D95,"") | T95: =IF($F95="ExpI",$D95,"") | U95: =IF($F95="ExpJ",$D95,"") | V95: =IF($F95="ExpK",$D95,"") | W95: =IF($F95="ExpL",$D95,"") | X95: =IF($F95="Expm",$D95,"") | Y95: =Y94+SUM(G95:K95)-SUM(L95:X95) -> 0
B96: Total | G96: =SUM(G6:G95) -> 0 | H96: =SUM(H6:H95) -> 0 | I96: =SUM(I6:I95) -> 0 | J96: =SUM(J6:J95) -> 0 | K96: =SUM(K6:K95) -> 0 | L96: =SUM(L6:L95) -> 0 | M96: =SUM(M6:M95) -> 0 | N96: =SUM(N6:N95) -> 0 | ... X96: =SUM(X6:X95) -> 0

Sheet June
A1: Cash Book June | D1: =Instructions!C3 -> Lucy's Tailored Tails
R3: Bank balance B/f | Y3: =IF(Instructions!C7="June",Instructions!C6,May!Y95) -> 0
A4: UPDATE THESE COLUMNS ONLY | G4: Income | L4: Expenditure
A5: Date | B5: Customer or Supplier | C5: Reference | D5: Amount | E5: Category | G5: =Categories!A2 -> Shop Sales | H5: =Categories!A3 -> Income 2 | I5: =Categories!A4 -> Income 3 | J5: =Categories!A5 -> Income 4 | K5: =Categories!A6 -> Income 5 | L5: =Categories!A7 -> Website Fees | M5: =Categories!A8 -> Exp 2 | N5: =Categories!A9 -> Exp 3 | O5: =Categories!A10 -> Exp 4 | P5: =Categories!A11 -> Exp 5 | Q5: =Categories!A12 -> Exp 6 | R5: =Categories!A13 -> Exp 7 | S5: =Categories!A14 -> Exp 8 | T5: =Categories!A15 -> Exp 9 | U5: =Categories!A16 -> Exp 10 | V5: =Categories!A17 -> Exp 11 | W5: =Categories!A18 -> Exp 12 | X5: =Categories!A19 -> Exp 13 | Y5: Balance
E6: Choose Account | F6: =IF($E6=Categories!$A$1,"",IF($E6=Categories!$A$2,Categories!$B$2,IF($E6=Categories!$A$3,Categories!$B$3,IF($E6=Categories!$A$4,Categories!$B$4,IF($E6=Categories!$A$5,Categories!$B$5,IF($E6=Categories!$A$6,Categories!$B$6,IF($E6=Categories!$A$7,Categories!$B$7,IF($E6=Categories!$A$8,Categories!$B$8,IF($E6=Categories!$A$9,Categories!$B$9,IF($E6=Categories!$A$10,Categories!$B$10,IF($E6=Categories!$A$11,Categories!$B$11,IF($E6=Categories!$A$12,Categories!$B$12,IF($E6=Categories!$A$13,Categories!$B$13,IF($E6=Categories!$A$14,Categories!$B$14,IF($E6=Categories!$A$15,Categories!$B$15,IF($E6=Categories!$A$16,Categories!$B$16,IF($E6=Categories!$A$17,Categories!$B$17,IF($E6=Categories!$A$18,Categories!$B$18,IF($E6=Categories!$A$19,Categories!$B$19))))))))))))))))))) -> FALSE | G6: =IF($F6="Inc1",$D6,"") | H6: =IF($F6="Inc2",$D6,"") | I6: =IF($F6="Int",$D6,"") | J6: =IF($F6="Inc4",$D6,"") | K6: =IF($F6="Inc5",$D6,"") | L6: =IF($F6="ExpA",$D6,"") | M6: =IF($F6="ExpB",$D6,"") | N6: =IF($F6="ExpC",$D6,"") | O6: =IF($F6="ExpD",$D6,"") | P6: =IF($F6="ExpE",$D6,"") | Q6: =IF($F6="ExpF",$D6,"") | R6: =IF($F6="ExpG",$D6,"") | S6: =IF($F6="ExpH",$D6,"") | T6: =IF($F6="ExpI",$D6,"") | U6: =IF($F6="ExpJ",$D6,"") | V6: =IF($F6="ExpK",$D6,"") | W6: =IF($F6="ExpL",$D6,"") | X6: =IF($F6="Expm",$D6,"") | Y6: =$Y$3+SUM(G6:K6)-SUM(L6:X6) -> 0
E7: Choose Account | F7: =IF($E7=Categories!$A$1,"",IF($E7=Categories!$A$2,Categories!$B$2,IF($E7=Categories!$A$3,Categories!$B$3,IF($E7=Categories!$A$4,Categories!$B$4,IF($E7=Categories!$A$5,Categories!$B$5,IF($E7=Categories!$A$6,Categories!$B$6,IF($E7=Categories!$A$7,Categories!$B$7,IF($E7=Categories!$A$8,Categories!$B$8,IF($E7=Categories!$A$9,Categories!$B$9,IF($E7=Categories!$A$10,Categories!$B$10,IF($E7=Categories!$A$11,Categories!$B$11,IF($E7=Categories!$A$12,Categories!$B$12,IF($E7=Categories!$A$13,Categories!$B$13,IF($E7=Categories!$A$14,Categories!$B$14,IF($E7=Categories!$A$15,Categories!$B$15,IF($E7=Categories!$A$16,Categories!$B$16,IF($E7=Categories!$A$17,Categories!$B$17,IF($E7=Categories!$A$18,Categories!$B$18,IF($E7=Categories!$A$19,Categories!$B$19))))))))))))))))))) -> FALSE | G7: =IF($F7="Inc1",$D7,"") | H7: =IF($F7="Inc2",$D7,"") | I7: =IF($F7="Int",$D7,"") | J7: =IF($F7="Inc4",$D7,"") | K7: =IF($F7="Inc5",$D7,"") | L7: =IF($F7="ExpA",$D7,"") | M7: =IF($F7="ExpB",$D7,"") | N7: =IF($F7="ExpC",$D7,"") | O7: =IF($F7="ExpD",$D7,"") | P7: =IF($F7="ExpE",$D7,"") | Q7: =IF($F7="ExpF",$D7,"") | R7: =IF($F7="ExpG",$D7,"") | S7: =IF($F7="ExpH",$D7,"") | T7: =IF($F7="ExpI",$D7,"") | U7: =IF($F7="ExpJ",$D7,"") | V7: =IF($F7="ExpK",$D7,"") | W7: =IF($F7="ExpL",$D7,"") | X7: =IF($F7="Expm",$D7,"") | Y7: =Y6+SUM(G7:K7)-SUM(L7:X7) -> 0
E8: Choose Account | F8: =IF($E8=Categories!$A$1,"",IF($E8=Categories!$A$2,Categories!$B$2,IF($E8=Categories!$A$3,Categories!$B$3,IF($E8=Categories!$A$4,Categories!$B$4,IF($E8=Categories!$A$5,Categories!$B$5,IF($E8=Categories!$A$6,Categories!$B$6,IF($E8=Categories!$A$7,Categories!$B$7,IF($E8=Categories!$A$8,Categories!$B$8,IF($E8=Categories!$A$9,Categories!$B$9,IF($E8=Categories!$A$10,Categories!$B$10,IF($E8=Categories!$A$11,Categories!$B$11,IF($E8=Categories!$A$12,Categories!$B$12,IF($E8=Categories!$A$13,Categories!$B$13,IF($E8=Categories!$A$14,Categories!$B$14,IF($E8=Categories!$A$15,Categories!$B$15,IF($E8=Categories!$A$16,Categories!$B$16,IF($E8=Categories!$A$17,Categories!$B$17,IF($E8=Categories!$A$18,Categories!$B$18,IF($E8=Categories!$A$19,Categories!$B$19))))))))))))))))))) -> FALSE | G8: =IF($F8="Inc1",$D8,"") | H8: =IF($F8="Inc2",$D8,"") | I8: =IF($F8="Int",$D8,"") | J8: =IF($F8="Inc4",$D8,"") | K8: =IF($F8="Inc5",$D8,"") | L8: =IF($F8="ExpA",$D8,"") | M8: =IF($F8="ExpB",$D8,"") | N8: =IF($F8="ExpC",$D8,"") | O8: =IF($F8="ExpD",$D8,"") | P8: =IF($F8="ExpE",$D8,"") | Q8: =IF($F8="ExpF",$D8,"") | R8: =IF($F8="ExpG",$D8,"") | S8: =IF($F8="ExpH",$D8,"") | T8: =IF($F8="ExpI",$D8,"") | U8: =IF($F8="ExpJ",$D8,"") | V8: =IF($F8="ExpK",$D8,"") | W8: =IF($F8="ExpL",$D8,"") | X8: =IF($F8="Expm",$D8,"") | Y8: =Y7+SUM(G8:K8)-SUM(L8:X8) -> 0
E9: Choose Account | F9: =IF($E9=Categories!$A$1,"",IF($E9=Categories!$A$2,Categories!$B$2,IF($E9=Categories!$A$3,Categories!$B$3,IF($E9=Categories!$A$4,Categories!$B$4,IF($E9=Categories!$A$5,Categories!$B$5,IF($E9=Categories!$A$6,Categories!$B$6,IF($E9=Categories!$A$7,Categories!$B$7,IF($E9=Categories!$A$8,Categories!$B$8,IF($E9=Categories!$A$9,Categories!$B$9,IF($E9=Categories!$A$10,Categories!$B$10,IF($E9=Categories!$A$11,Categories!$B$11,IF($E9=Categories!$A$12,Categories!$B$12,IF($E9=Categories!$A$13,Categories!$B$13,IF($E9=Categories!$A$14,Categories!$B$14,IF($E9=Categories!$A$15,Categories!$B$15,IF($E9=Categories!$A$16,Categories!$B$16,IF($E9=Categories!$A$17,Categories!$B$17,IF($E9=Categories!$A$18,Categories!$B$18,IF($E9=Categories!$A$19,Categories!$B$19))))))))))))))))))) -> FALSE | G9: =IF($F9="Inc1",$D9,"") | H9: =IF($F9="Inc2",$D9,"") | I9: =IF($F9="Int",$D9,"") | J9: =IF($F9="Inc4",$D9,"") | K9: =IF($F9="Inc5",$D9,"") | L9: =IF($F9="ExpA",$D9,"") | M9: =IF($F9="ExpB",$D9,"") | N9: =IF($F9="ExpC",$D9,"") | O9: =IF($F9="ExpD",$D9,"") | P9: =IF($F9="ExpE",$D9,"") | Q9: =IF($F9="ExpF",$D9,"") | R9: =IF($F9="ExpG",$D9,"") | S9: =IF($F9="ExpH",$D9,"") | T9: =IF($F9="ExpI",$D9,"") | U9: =IF($F9="ExpJ",$D9,"") | V9: =IF($F9="ExpK",$D9,"") | W9: =IF($F9="ExpL",$D9,"") | X9: =IF($F9="Expm",$D9,"") | Y9: =Y8+SUM(G9:K9)-SUM(L9:X9) -> 0
E10: Choose Account | F10: =IF($E10=Categories!$A$1,"",IF($E10=Categories!$A$2,Categories!$B$2,IF($E10=Categories!$A$3,Categories!$B$3,IF($E10=Categories!$A$4,Categories!$B$4,IF($E10=Categories!$A$5,Categories!$B$5,IF($E10=Categories!$A$6,Categories!$B$6,IF($E10=Categories!$A$7,Categories!$B$7,IF($E10=Categories!$A$8,Categories!$B$8,IF($E10=Categories!$A$9,Categories!$B$9,IF($E10=Categories!$A$10,Categories!$B$10,IF($E10=Categories!$A$11,Categories!$B$11,IF($E10=Categories!$A$12,Categories!$B$12,IF($E10=Categories!$A$13,Categories!$B$13,IF($E10=Categories!$A$14,Categories!$B$14,IF($E10=Categories!$A$15,Categories!$B$15,IF($E10=Categories!$A$16,Categories!$B$16,IF($E10=Categories!$A$17,Categories!$B$17,IF($E10=Categories!$A$18,Categories!$B$18,IF($E10=Categories!$A$19,Categories!$B$19))))))))))))))))))) -> FALSE | G10: =IF($F10="Inc1",$D10,"") | H10: =IF($F10="Inc2",$D10,"") | I10: =IF($F10="Int",$D10,"") | J10: =IF($F10="Inc4",$D10,"") | K10: =IF($F10="Inc5",$D10,"") | L10: =IF($F10="ExpA",$D10,"") | M10: =IF($F10="ExpB",$D10,"") | N10: =IF($F10="ExpC",$D10,"") | O10: =IF($F10="ExpD",$D10,"") | P10: =IF($F10="ExpE",$D10,"") | Q10: =IF($F10="ExpF",$D10,"") | R10: =IF($F10="ExpG",$D10,"") | S10: =IF($F10="ExpH",$D10,"") | T10: =IF($F10="ExpI",$D10,"") | U10: =IF($F10="ExpJ",$D10,"") | V10: =IF($F10="ExpK",$D10,"") | W10: =IF($F10="ExpL",$D10,"") | X10: =IF($F10="Expm",$D10,"") | Y10: =Y9+SUM(G10:K10)-SUM(L10:X10) -> 0
E11: Choose Account | F11: =IF($E11=Categories!$A$1,"",IF($E11=Categories!$A$2,Categories!$B$2,IF($E11=Categories!$A$3,Categories!$B$3,IF($E11=Categories!$A$4,Categories!$B$4,IF($E11=Categories!$A$5,Categories!$B$5,IF($E11=Categories!$A$6,Categories!$B$6,IF($E11=Categories!$A$7,Categories!$B$7,IF($E11=Categories!$A$8,Categories!$B$8,IF($E11=Categories!$A$9,Categories!$B$9,IF($E11=Categories!$A$10,Categories!$B$10,IF($E11=Categories!$A$11,Categories!$B$11,IF($E11=Categories!$A$12,Categories!$B$12,IF($E11=Categories!$A$13,Categories!$B$13,IF($E11=Categories!$A$14,Categories!$B$14,IF($E11=Categories!$A$15,Categories!$B$15,IF($E11=Categories!$A$16,Categories!$B$16,IF($E11=Categories!$A$17,Categories!$B$17,IF($E11=Categories!$A$18,Categories!$B$18,IF($E11=Categories!$A$19,Categories!$B$19))))))))))))))))))) -> FALSE | G11: =IF($F11="Inc1",$D11,"") | H11: =IF($F11="Inc2",$D11,"") | I11: =IF($F11="Int",$D11,"") | J11: =IF($F11="Inc4",$D11,"") | K11: =IF($F11="Inc5",$D11,"") | L11: =IF($F11="ExpA",$D11,"") | M11: =IF($F11="ExpB",$D11,"") | N11: =IF($F11="ExpC",$D11,"") | O11: =IF($F11="ExpD",$D11,"") | P11: =IF($F11="ExpE",$D11,"") | Q11: =IF($F11="ExpF",$D11,"") | R11: =IF($F11="ExpG",$D11,"") | S11: =IF($F11="ExpH",$D11,"") | T11: =IF($F11="ExpI",$D11,"") | U11: =IF($F11="ExpJ",$D11,"") | V11: =IF($F11="ExpK",$D11,"") | W11: =IF($F11="ExpL",$D11,"") | X11: =IF($F11="Expm",$D11,"") | Y11: =Y10+SUM(G11:K11)-SUM(L11:X11) -> 0
E12: Choose Account | F12: =IF($E12=Categories!$A$1,"",IF($E12=Categories!$A$2,Categories!$B$2,IF($E12=Categories!$A$3,Categories!$B$3,IF($E12=Categories!$A$4,Categories!$B$4,IF($E12=Categories!$A$5,Categories!$B$5,IF($E12=Categories!$A$6,Categories!$B$6,IF($E12=Categories!$A$7,Categories!$B$7,IF($E12=Categories!$A$8,Categories!$B$8,IF($E12=Categories!$A$9,Categories!$B$9,IF($E12=Categories!$A$10,Categories!$B$10,IF($E12=Categories!$A$11,Categories!$B$11,IF($E12=Categories!$A$12,Categories!$B$12,IF($E12=Categories!$A$13,Categories!$B$13,IF($E12=Categories!$A$14,Categories!$B$14,IF($E12=Categories!$A$15,Categories!$B$15,IF($E12=Categories!$A$16,Categories!$B$16,IF($E12=Categories!$A$17,Categories!$B$17,IF($E12=Categories!$A$18,Categories!$B$18,IF($E12=Categories!$A$19,Categories!$B$19))))))))))))))))))) -> FALSE | G12: =IF($F12="Inc1",$D12,"") | H12: =IF($F12="Inc2",$D12,"") | I12: =IF($F12="Int",$D12,"") | J12: =IF($F12="Inc4",$D12,"") | K12: =IF($F12="Inc5",$D12,"") | L12: =IF($F12="ExpA",$D12,"") | M12: =IF($F12="ExpB",$D12,"") | N12: =IF($F12="ExpC",$D12,"") | O12: =IF($F12="ExpD",$D12,"") | P12: =IF($F12="ExpE",$D12,"") | Q12: =IF($F12="ExpF",$D12,"") | R12: =IF($F12="ExpG",$D12,"") | S12: =IF($F12="ExpH",$D12,"") | T12: =IF($F12="ExpI",$D12,"") | U12: =IF($F12="ExpJ",$D12,"") | V12: =IF($F12="ExpK",$D12,"") | W12: =IF($F12="ExpL",$D12,"") | X12: =IF($F12="Expm",$D12,"") | Y12: =Y11+SUM(G12:K12)-SUM(L12:X12) -> 0
E13: Choose Account | F13: =IF($E13=Categories!$A$1,"",IF($E13=Categories!$A$2,Categories!$B$2,IF($E13=Categories!$A$3,Categories!$B$3,IF($E13=Categories!$A$4,Categories!$B$4,IF($E13=Categories!$A$5,Categories!$B$5,IF($E13=Categories!$A$6,Categories!$B$6,IF($E13=Categories!$A$7,Categories!$B$7,IF($E13=Categories!$A$8,Categories!$B$8,IF($E13=Categories!$A$9,Categories!$B$9,IF($E13=Categories!$A$10,Categories!$B$10,IF($E13=Categories!$A$11,Categories!$B$11,IF($E13=Categories!$A$12,Categories!$B$12,IF($E13=Categories!$A$13,Categories!$B$13,IF($E13=Categories!$A$14,Categories!$B$14,IF($E13=Categories!$A$15,Categories!$B$15,IF($E13=Categories!$A$16,Categories!$B$16,IF($E13=Categories!$A$17,Categories!$B$17,IF($E13=Categories!$A$18,Categories!$B$18,IF($E13=Categories!$A$19,Categories!$B$19))))))))))))))))))) -> FALSE | G13: =IF($F13="Inc1",$D13,"") | H13: =IF($F13="Inc2",$D13,"") | I13: =IF($F13="Int",$D13,"") | J13: =IF($F13="Inc4",$D13,"") | K13: =IF($F13="Inc5",$D13,"") | L13: =IF($F13="ExpA",$D13,"") | M13: =IF($F13="ExpB",$D13,"") | N13: =IF($F13="ExpC",$D13,"") | O13: =IF($F13="ExpD",$D13,"") | P13: =IF($F13="ExpE",$D13,"") | Q13: =IF($F13="ExpF",$D13,"") | R13: =IF($F13="ExpG",$D13,"") | S13: =IF($F13="ExpH",$D13,"") | T13: =IF($F13="ExpI",$D13,"") | U13: =IF($F13="ExpJ",$D13,"") | V13: =IF($F13="ExpK",$D13,"") | W13: =IF($F13="ExpL",$D13,"") | X13: =IF($F13="Expm",$D13,"") | Y13: =Y12+SUM(G13:K13)-SUM(L13:X13) -> 0
E14: Choose Account | F14: =IF($E14=Categories!$A$1,"",IF($E14=Categories!$A$2,Categories!$B$2,IF($E14=Categories!$A$3,Categories!$B$3,IF($E14=Categories!$A$4,Categories!$B$4,IF($E14=Categories!$A$5,Categories!$B$5,IF($E14=Categories!$A$6,Categories!$B$6,IF($E14=Categories!$A$7,Categories!$B$7,IF($E14=Categories!$A$8,Categories!$B$8,IF($E14=Categories!$A$9,Categories!$B$9,IF($E14=Categories!$A$10,Categories!$B$10,IF($E14=Categories!$A$11,Categories!$B$11,IF($E14=Categories!$A$12,Categories!$B$12,IF($E14=Categories!$A$13,Categories!$B$13,IF($E14=Categories!$A$14,Categories!$B$14,IF($E14=Categories!$A$15,Categories!$B$15,IF($E14=Categories!$A$16,Categories!$B$16,IF($E14=Categories!$A$17,Categories!$B$17,IF($E14=Categories!$A$18,Categories!$B$18,IF($E14=Categories!$A$19,Categories!$B$19))))))))))))))))))) -> FALSE | G14: =IF($F14="Inc1",$D14,"") | H14: =IF($F14="Inc2",$D14,"") | I14: =IF($F14="Int",$D14,"") | J14: =IF($F14="Inc4",$D14,"") | K14: =IF($F14="Inc5",$D14,"") | L14: =IF($F14="ExpA",$D14,"") | M14: =IF($F14="ExpB",$D14,"") | N14: =IF($F14="ExpC",$D14,"") | O14: =IF($F14="ExpD",$D14,"") | P14: =IF($F14="ExpE",$D14,"") | Q14: =IF($F14="ExpF",$D14,"") | R14: =IF($F14="ExpG",$D14,"") | S14: =IF($F14="ExpH",$D14,"") | T14: =IF($F14="ExpI",$D14,"") | U14: =IF($F14="ExpJ",$D14,"") | V14: =IF($F14="ExpK",$D14,"") | W14: =IF($F14="ExpL",$D14,"") | X14: =IF($F14="Expm",$D14,"") | Y14: =Y13+SUM(G14:K14)-SUM(L14:X14) -> 0
